{
  "session_1747286049302": {
    "id": "session_1747286049302",
    "failure_id": "1747286049302",
    "created_at": "2025-05-15T05:14:09.307Z",
    "debug_steps": [
      {
        "step": 1,
        "name": "Understand the System",
        "status": "pending",
        "started_at": "2025-05-15T05:14:09.307Z",
        "completed_at": null,
        "llm_analysis": null
      }
    ]
  },
  "session_1747286061306": {
    "id": "session_1747286061306",
    "failure_id": "1747286061306",
    "created_at": "2025-05-15T05:14:21.308Z",
    "debug_steps": [
      {
        "step": 1,
        "name": "Understand the System",
        "status": "completed",
        "started_at": "2025-05-15T05:14:21.308Z",
        "completed_at": "2025-05-15T05:14:41.734Z",
        "llm_analysis": "The test is failing because of an AttributeError: __name__. This happens when trying to access the __name__ attribute on a mock function. In the with_retry decorator, it's trying to use func.__name__ but since the function is a MagicMock object, it doesn't have this attribute by default. The solution would be to ensure the mock has a __name__ attribute or modify the decorator to handle this case."
      },
      {
        "step": 2,
        "name": "Make It Fail",
        "status": "pending",
        "started_at": "2025-05-15T05:14:41.734Z",
        "completed_at": null,
        "llm_analysis": null
      }
    ]
  }
}